<?xml version="1.0" ?>
<sdf version='1.7'>
  <world name='default'>
    <light name='sun' type='directional'>
      <cast_shadows>1</cast_shadows>
      <pose frame=''>0 0 10 0 -0 0</pose>
      <diffuse>0.8 0.8 0.8 1</diffuse>
      <specular>0.2 0.2 0.2 1</specular>
      <attenuation>
        <range>1000</range>
        <constant>0.9</constant>
        <linear>0.01</linear>
        <quadratic>0.001</quadratic>
      </attenuation>
      <direction>-0.5 0.1 -0.9</direction>
    </light>
    <model name='ground_plane'>
      <static>1</static>
      <link name='link'>
        <collision name='collision'>
          <geometry>
            <plane>
              <normal>0 0 1</normal>
              <size>100 100</size>
            </plane>
          </geometry>
          <surface>
            <contact>
              <collide_bitmask>65535</collide_bitmask>
              <ode/>
            </contact>
            <friction>
              <ode>
                <mu>100</mu>
                <mu2>50</mu2>
              </ode>
              <torsional>
                <ode/>
              </torsional>
            </friction>
            <bounce/>
          </surface>
          <max_contacts>10</max_contacts>
        </collision>
        <visual name='visual'>
          <cast_shadows>0</cast_shadows>
          <geometry>
            <plane>
              <normal>0 0 1</normal>
              <size>100 100</size>
            </plane>
          </geometry>
          <material>
            <script>
              <uri>file://media/materials/scripts/gazebo.material</uri>
              <name>Gazebo/Grey</name>
            </script>
          </material>
        </visual>
        <self_collide>0</self_collide>
        <enable_wind>0</enable_wind>
        <kinematic>0</kinematic>
      </link>
    </model>
    <gravity>0 0 -9.8</gravity>
    <magnetic_field>6e-06 2.3e-05 -4.2e-05</magnetic_field>
    <atmosphere type='adiabatic'/>
    <physics name='default_physics' default='0' type='ode'>
      <max_step_size>0.001</max_step_size>
      <real_time_factor>1</real_time_factor>
      <real_time_update_rate>1000</real_time_update_rate>
    </physics>
    <scene>
      <ambient>0.4 0.4 0.4 1</ambient>
      <background>0.7 0.7 0.7 1</background>
      <shadows>1</shadows>
    </scene>
    <audio>
      <device>default</device>
    </audio>
    <wind/>
    <spherical_coordinates>
      <surface_model>EARTH_WGS84</surface_model>
      <latitude_deg>0</latitude_deg>
      <longitude_deg>0</longitude_deg>
      <elevation>0</elevation>
      <heading_deg>0</heading_deg>
    </spherical_coordinates>
    <model name='rom2109'>
      <link name='base_link'>
        <pose frame=''>0 0 0 0 -0 0</pose>
        <inertial>
          <pose frame=''>0.002369 -0.000503 0.125748 0 -0 0</pose>
          <mass>4.88202</mass>
          <inertia>
            <ixx>0.0954286</ixx>
            <ixy>6.74652e-05</ixy>
            <ixz>0.000772824</ixz>
            <iyy>0.0992217</iyy>
            <iyz>0.000420135</iyz>
            <izz>0.0343551</izz>
          </inertia>
        </inertial>
        <collision name='base_link_collision'>
          <pose frame=''>0 0 0 0 -0 0</pose>
          <geometry>
            <mesh>
              <scale>1 1 1</scale>
              <uri>/home/mr_robot/ros2/ros2_ws/src/rom2109_description/meshes/base_link.STL</uri>
            </mesh>
          </geometry>
          <surface>
            <contact>
              <ode/>
            </contact>
            <friction>
              <ode/>
              <torsional>
                <ode/>
              </torsional>
            </friction>
            <bounce/>
          </surface>
          <max_contacts>10</max_contacts>
        </collision>
        <collision name='base_link_fixed_joint_lump__plate1_collision_1'>
          <pose frame=''>-0.003873 0 0.15505 0 -0 0</pose>
          <geometry>
            <mesh>
              <scale>1 1 1</scale>
              <uri>/home/mr_robot/ros2/ros2_ws/src/rom2109_description/meshes/plate1.STL</uri>
            </mesh>
          </geometry>
          <surface>
            <contact>
              <ode/>
            </contact>
            <friction>
              <ode/>
              <torsional>
                <ode/>
              </torsional>
            </friction>
            <bounce/>
          </surface>
          <max_contacts>10</max_contacts>
        </collision>
        <collision name='base_link_fixed_joint_lump__camera_collision_2'>
          <pose frame=''>0.105627 0.005577 0.14255 0 -0 0</pose>
          <geometry>
            <mesh>
              <scale>1 1 1</scale>
              <uri>/home/mr_robot/ros2/ros2_ws/src/rom2109_description/meshes/camera.STL</uri>
            </mesh>
          </geometry>
          <max_contacts>10</max_contacts>
          <surface>
            <contact>
              <ode/>
            </contact>
            <bounce/>
            <friction>
              <torsional>
                <ode/>
              </torsional>
              <ode/>
            </friction>
          </surface>
        </collision>
        <collision name='base_link_fixed_joint_lump__lidar_collision_3'>
          <pose frame=''>0.012125 -0.00158 0.18765 0 -0 0</pose>
          <geometry>
            <mesh>
              <scale>1 1 1</scale>
              <uri>/home/mr_robot/ros2/ros2_ws/src/rom2109_description/meshes/lidar.STL</uri>
            </mesh>
          </geometry>
          <surface>
            <contact>
              <ode/>
            </contact>
            <friction>
              <ode/>
              <torsional>
                <ode/>
              </torsional>
            </friction>
            <bounce/>
          </surface>
          <max_contacts>10</max_contacts>
        </collision>
        <collision name='base_link_fixed_joint_lump__plate2_collision_4'>
          <pose frame=''>-0.003873 0 0.2668 0 -0 0</pose>
          <geometry>
            <mesh>
              <scale>1 1 1</scale>
              <uri>/home/mr_robot/ros2/ros2_ws/src/rom2109_description/meshes/plate2.STL</uri>
            </mesh>
          </geometry>
          <surface>
            <contact>
              <ode/>
            </contact>
            <friction>
              <ode/>
              <torsional>
                <ode/>
              </torsional>
            </friction>
            <bounce/>
          </surface>
          <max_contacts>10</max_contacts>
        </collision>
        <collision name='base_link_fixed_joint_lump__plate3_collision_5'>
          <pose frame=''>-0.003873 0 0.424802 0 -0 0</pose>
          <geometry>
            <mesh>
              <scale>1 1 1</scale>
              <uri>/home/mr_robot/ros2/ros2_ws/src/rom2109_description/meshes/plate3.STL</uri>
            </mesh>
          </geometry>
          <surface>
            <contact>
              <ode/>
            </contact>
            <friction>
              <ode/>
              <torsional>
                <ode/>
              </torsional>
            </friction>
            <bounce/>
          </surface>
          <max_contacts>10</max_contacts>
        </collision>
        <visual name='base_link_visual'>
          <pose frame=''>0 0 0 0 -0 0</pose>
          <geometry>
            <mesh>
              <scale>1 1 1</scale>
              <uri>/home/mr_robot/ros2/ros2_ws/src/rom2109_description/meshes/base_link.STL</uri>
            </mesh>
          </geometry>
          <material>
            <script>
              <name>Gazebo/Black</name>
              <uri>file://media/materials/scripts/gazebo.material</uri>
            </script>
          </material>
        </visual>
        <visual name='base_link_fixed_joint_lump__plate1_visual_1'>
          <pose frame=''>-0.003873 0 0.15505 0 -0 0</pose>
          <geometry>
            <mesh>
              <scale>1 1 1</scale>
              <uri>/home/mr_robot/ros2/ros2_ws/src/rom2109_description/meshes/plate1.STL</uri>
            </mesh>
          </geometry>
          <material>
            <script>
              <name>Gazebo/Yellow</name>
              <uri>file://media/materials/scripts/gazebo.material</uri>
            </script>
          </material>
        </visual>
        <visual name='base_link_fixed_joint_lump__camera_visual_2'>
          <pose frame=''>0.105627 0.005577 0.14255 0 -0 0</pose>
          <geometry>
            <mesh>
              <scale>1 1 1</scale>
              <uri>/home/mr_robot/ros2/ros2_ws/src/rom2109_description/meshes/camera.STL</uri>
            </mesh>
          </geometry>
        </visual>
        <visual name='base_link_fixed_joint_lump__lidar_visual_3'>
          <pose frame=''>0.012125 -0.00158 0.18765 0 -0 0</pose>
          <geometry>
            <mesh>
              <scale>1 1 1</scale>
              <uri>/home/mr_robot/ros2/ros2_ws/src/rom2109_description/meshes/lidar.STL</uri>
            </mesh>
          </geometry>
          <material>
            <script>
              <uri>__default__</uri>
              <name>__default__</name>
            </script>
          </material>
        </visual>
        <visual name='base_link_fixed_joint_lump__plate2_visual_4'>
          <pose frame=''>-0.003873 0 0.2668 0 -0 0</pose>
          <geometry>
            <mesh>
              <scale>1 1 1</scale>
              <uri>/home/mr_robot/ros2/ros2_ws/src/rom2109_description/meshes/plate2.STL</uri>
            </mesh>
          </geometry>
          <material>
            <script>
              <name>Gazebo/Yellow</name>
              <uri>file://media/materials/scripts/gazebo.material</uri>
            </script>
          </material>
        </visual>
        <visual name='base_link_fixed_joint_lump__plate3_visual_5'>
          <pose frame=''>-0.003873 0 0.424802 0 -0 0</pose>
          <geometry>
            <mesh>
              <scale>1 1 1</scale>
              <uri>/home/mr_robot/ros2/ros2_ws/src/rom2109_description/meshes/plate3.STL</uri>
            </mesh>
          </geometry>
          <material>
            <script>
              <name>Gazebo/Yellow</name>
              <uri>file://media/materials/scripts/gazebo.material</uri>
            </script>
          </material>
        </visual>
        <velocity_decay/>
        <velocity_decay/>
        <velocity_decay/>
        <sensor name='head_hokuyo_sensor' type='ray'>
          <visualize>1</visualize>
          <update_rate>40</update_rate>
          <ray>
            <scan>
              <horizontal>
                <samples>720</samples>
                <resolution>1</resolution>
                <min_angle>-1.5708</min_angle>
                <max_angle>1.5708</max_angle>
              </horizontal>
              <vertical>
                <samples>1</samples>
                <min_angle>0</min_angle>
                <max_angle>0</max_angle>
              </vertical>
            </scan>
            <range>
              <min>0.1</min>
              <max>30</max>
              <resolution>0.01</resolution>
            </range>
            <noise>
              <type>gaussian</type>
              <mean>0</mean>
              <stddev>0.01</stddev>
            </noise>
          </ray>
          <plugin name='gazebo_ros_head_hokuyo_controller' filename='libgazebo_ros_laser.so'>
            <topicName>/scan</topicName>
            <frameName>lidar</frameName>
            <robotNamespace>/</robotNamespace>
          </plugin>
          <pose frame=''>0.012125 -0.00158 0.18765 0 -0 0</pose>
        </sensor>
        <velocity_decay/>
        <gravity>1</gravity>
        <velocity_decay/>
        <self_collide>0</self_collide>
        <enable_wind>0</enable_wind>
        <kinematic>0</kinematic>
      </link>
      <link name='left_wheel'>
        <pose frame=''>0 0.098333 0.02605 0 -0 0</pose>
        <inertial>
          <pose frame=''>0 0.000949 0 0 -0 0</pose>
          <mass>2.88258</mass>
          <inertia>
            <ixx>0.00290152</ixx>
            <ixy>-9.17143e-15</ixy>
            <ixz>6.05063e-15</ixz>
            <iyy>0.00524996</iyy>
            <iyz>-2.70786e-15</iyz>
            <izz>0.00290152</izz>
          </inertia>
        </inertial>
        <collision name='left_wheel_collision'>
          <pose frame=''>0 0 0 0 -0 0</pose>
          <geometry>
            <mesh>
              <scale>1 1 1</scale>
              <uri>/home/mr_robot/ros2/ros2_ws/src/rom2109_description/meshes/left_wheel.STL</uri>
            </mesh>
          </geometry>
          <max_contacts>10</max_contacts>
          <surface>
            <contact>
              <ode/>
            </contact>
            <bounce/>
            <friction>
              <torsional>
                <ode/>
              </torsional>
              <ode/>
            </friction>
          </surface>
        </collision>
        <visual name='left_wheel_visual'>
          <pose frame=''>0 0 0 0 -0 0</pose>
          <geometry>
            <mesh>
              <scale>1 1 1</scale>
              <uri>/home/mr_robot/ros2/ros2_ws/src/rom2109_description/meshes/left_wheel.STL</uri>
            </mesh>
          </geometry>
        </visual>
        <self_collide>0</self_collide>
        <enable_wind>0</enable_wind>
        <kinematic>0</kinematic>
      </link>
      <joint name='left_wheel_joint' type='revolute'>
        <child>left_wheel</child>
        <parent>base_link</parent>
        <axis>
          <xyz>0 1 0</xyz>
          <limit>
            <lower>-1e+16</lower>
            <upper>1e+16</upper>
          </limit>
          <dynamics>
            <spring_reference>0</spring_reference>
            <spring_stiffness>0</spring_stiffness>
          </dynamics>
          <use_parent_model_frame>1</use_parent_model_frame>
        </axis>
      </joint>
      <link name='right_wheel'>
        <pose frame=''>0 -0.098333 0.02605 0 -0 0</pose>
        <inertial>
          <pose frame=''>0 -0.000949 -0 0 -0 0</pose>
          <mass>2.88258</mass>
          <inertia>
            <ixx>0.00290152</ixx>
            <ixy>8.84503e-19</ixy>
            <ixz>1.39522e-19</ixz>
            <iyy>0.00524996</iyy>
            <iyz>8.13663e-18</iyz>
            <izz>0.00290152</izz>
          </inertia>
        </inertial>
        <collision name='right_wheel_collision'>
          <pose frame=''>0 0 0 0 -0 0</pose>
          <geometry>
            <mesh>
              <scale>1 1 1</scale>
              <uri>/home/mr_robot/ros2/ros2_ws/src/rom2109_description/meshes/right_wheel.STL</uri>
            </mesh>
          </geometry>
          <max_contacts>10</max_contacts>
          <surface>
            <contact>
              <ode/>
            </contact>
            <bounce/>
            <friction>
              <torsional>
                <ode/>
              </torsional>
              <ode/>
            </friction>
          </surface>
        </collision>
        <visual name='right_wheel_visual'>
          <pose frame=''>0 0 0 0 -0 0</pose>
          <geometry>
            <mesh>
              <scale>1 1 1</scale>
              <uri>/home/mr_robot/ros2/ros2_ws/src/rom2109_description/meshes/right_wheel.STL</uri>
            </mesh>
          </geometry>
        </visual>
        <self_collide>0</self_collide>
        <enable_wind>0</enable_wind>
        <kinematic>0</kinematic>
      </link>
      <joint name='right_wheel_joint' type='revolute'>
        <child>right_wheel</child>
        <parent>base_link</parent>
        <axis>
          <xyz>0 1 0</xyz>
          <limit>
            <lower>-1e+16</lower>
            <upper>1e+16</upper>
          </limit>
          <dynamics>
            <spring_reference>0</spring_reference>
            <spring_stiffness>0</spring_stiffness>
          </dynamics>
          <use_parent_model_frame>1</use_parent_model_frame>
        </axis>
      </joint>
      <plugin name='gazebo_ros_control' filename='libgazebo_ros_contol.so'>
        <robotNamespace>/</robotNamespace>
      </plugin>
      <static>0</static>
      <plugin name='differential_drive_controller' filename='libgazebo_ros_diff_drive.so'>
        <alwaysOn>1</alwaysOn>
        <legacyMode>1</legacyMode>
        <updateRate>100</updateRate>
        <leftJoint>right_wheel_joint</leftJoint>
        <rightJoint>left_wheel_joint</rightJoint>
        <wheelSeparation>0.27</wheelSeparation>
        <wheelDiameter>0.07</wheelDiameter>
        <torque>200</torque>
        <commandTopic>cmd_vel</commandTopic>
        <odometryTopic>odom</odometryTopic>
        <odometryFrame>odom</odometryFrame>
        <robotBaseFrame>base_link</robotBaseFrame>
        <publishWheelTF>0</publishWheelTF>
        <publishWheelJointState>1</publishWheelJointState>
        <robotNamespace>/</robotNamespace>
      </plugin>
      <pose frame=''>0 0 0 0 -0 0</pose>
    </model>
    <state world_name='default'>
      <sim_time>10 808000000</sim_time>
      <real_time>172 307134682</real_time>
      <wall_time>1675315258 473637304</wall_time>
      <iterations>10808</iterations>
      <model name='ground_plane'>
        <pose frame=''>0 0 0 0 -0 0</pose>
        <scale>1 1 1</scale>
        <link name='link'>
          <pose frame=''>0 0 0 0 -0 0</pose>
          <velocity>0 0 0 0 -0 0</velocity>
          <acceleration>0 0 0 0 -0 0</acceleration>
          <wrench>0 0 0 0 -0 0</wrench>
        </link>
      </model>
      <model name='rom2109'>
        <pose frame=''>0.000345 -0.000594 0.023999 -0.000126 0.033207 0.003061</pose>
        <scale>1 1 1</scale>
        <link name='base_link'>
          <pose frame=''>0.000345 -0.000594 0.023999 -0.000126 0.033207 0.003061</pose>
          <velocity>0.00023 8.8e-05 -0.000636 0.005724 0.009742 2.7e-05</velocity>
          <acceleration>0.273298 -3.42425 -3.09805 1.19399 1.30839 -1.22564</acceleration>
          <wrench>1.33424 -16.7172 -15.1247 0 -0 0</wrench>
        </link>
        <link name='left_wheel'>
          <pose frame=''>0.000909 0.097745 0.050022 -0.000151 0.012437 0.003065</pose>
          <velocity>0.000481 -0.000131 -6e-05 0.002773 0.009607 0.000211</velocity>
          <acceleration>0.083861 -0.659069 -0.114686 0.788116 1.46322 -2.56986</acceleration>
          <wrench>0.241735 -1.89982 -0.330591 0 -0 0</wrench>
        </link>
        <link name='right_wheel'>
          <pose frame=''>0.001511 -0.09892 0.050047 -0.000102 -0.034302 0.003068</pose>
          <velocity>0.000482 -0.000187 -0.001234 -0.000241 0.009726 0.000366</velocity>
          <acceleration>0.095916 -0.838931 -6.04113 -2.58433 1.16244 -2.0478</acceleration>
          <wrench>0.276487 -2.41829 -17.414 0 -0 0</wrench>
        </link>
      </model>
      <light name='sun'>
        <pose frame=''>0 0 10 0 -0 0</pose>
      </light>
    </state>
    <gui fullscreen='0'>
      <camera name='user_camera'>
        <pose frame=''>5.0361 -5.0499 1.78501 0 0.275643 2.35619</pose>
        <view_controller>orbit</view_controller>
        <projection_type>perspective</projection_type>
      </camera>
    </gui>
  </world>
</sdf>
